<mujoco model="sawyer">
    <compiler angle="radian" meshdir="/Users/aykut/Desktop/development/cito_ws/src/cito/model/mesh/sawyer/" />
    <size njmax="500" nconmax="100" />
    <asset>
        <mesh name="pedestal" file="pedestal.stl" />
        <mesh name="base" file="base.stl" />
        <mesh name="l0" file="l0.stl" />
        <mesh name="head" file="head.stl" />
        <mesh name="l1" file="l1.stl" />
        <mesh name="l2" file="l2.stl" />
        <mesh name="l3" file="l3.stl" />
        <mesh name="l4" file="l4.stl" />
        <mesh name="l5" file="l5.stl" />
        <mesh name="l6" file="l6.stl" />
    </asset>
    <worldbody>
        <geom pos="0.26 0.345 -0.91488" quat="0.5 0.5 -0.5 -0.5" type="mesh" rgba="0.2 0.2 0.2 1" mesh="pedestal" />
        <geom type="mesh" rgba="0.5 0.1 0.1 1" mesh="base" />
        <body name="right_l0" pos="0 0 0.08">
            <inertial pos="0.0200058 0.00845202 0.201992" quat="0.922356 0.0138555 -0.0834249 0.376971" mass="6.901" diaginertia="0.153016 0.140863 0.0256132" />
            <joint name="right_j0" pos="0 0 0" axis="0 0 1" limited="true" range="-3.0503 3.0503" />
            <geom type="mesh" rgba="0.5 0.1 0.1 1" mesh="l0" />
            <geom pos="0 0 0.2965" type="mesh" rgba="0.5 0.1 0.1 1" mesh="head" />
            <body name="right_l1" pos="0.081 0.05 0.237" quat="0.5 -0.5 0.5 0.5">
                <inertial pos="-0.0030849 -0.026811 0.092521" quat="0.424888 0.891987 0.132364 -0.0794294" mass="4.505" diaginertia="0.0224339 0.0221624 0.00970971" />
                <joint name="right_j1" pos="0 0 0" axis="0 0 1" limited="true" range="-3.8095 2.2736" />
                <geom type="mesh" rgba="0.5 0.1 0.1 1" mesh="l1" />
                <body name="right_l2" pos="0 -0.14 0.1425" quat="0.707107 0.707107 0 0">
                    <inertial pos="-0.00016044 -0.014967 0.13582" quat="0.707831 -0.0524761 0.0516006 0.702537" mass="1.745" diaginertia="0.0257928 0.025506 0.00292516" />
                    <joint name="right_j2" pos="0 0 0" axis="0 0 1" limited="true" range="-3.0426 3.0426" />
                    <geom type="mesh" rgba="0.5 0.1 0.1 1" mesh="l2" />
                    <body name="right_l3" pos="0 -0.042 0.26" quat="0.707107 -0.707107 0 0">
                        <inertial pos="-0.0048135 -0.0281 -0.084154" quat="0.902999 0.385391 -0.0880901 0.168247" mass="2.5097" diaginertia="0.0102404 0.0096997 0.00369622" />
                        <joint name="right_j3" pos="0 0 0" axis="0 0 1" limited="true" range="-3.0439 3.0439" />
                        <geom type="mesh" rgba="0.5 0.1 0.1 1" mesh="l3" />
                        <body name="right_l4" pos="0 -0.125 -0.1265" quat="0.707107 0.707107 0 0">
                            <inertial pos="-0.00188917 0.00689948 0.134095" quat="0.803247 0.031244 -0.0298409 0.594077" mass="1.1137" diaginertia="0.0136555 0.0135498 0.00127385" />
                            <joint name="right_j4" pos="0 0 0" axis="0 0 1" limited="true" range="-2.9761 2.9761" />
                            <geom type="mesh" rgba="0.5 0.1 0.1 1" mesh="l4" />
                            <body name="right_l5" pos="0 0.031 0.275" quat="0.707107 -0.707107 0 0">
                                <inertial pos="0.0061133 -0.023697 0.076416" quat="0.404076 0.9135 0.0473125 0.00158335" mass="1.5625" diaginertia="0.00474131 0.00422857 0.00190672" />
                                <joint name="right_j5" pos="0 0 0" axis="0 0 1" limited="true" range="-2.9761 2.9761" />
                                <geom type="mesh" rgba="0.5 0.1 0.1 1" mesh="l5" />
                                <body name="right_l6" pos="0 -0.11 0.1053" quat="0.0616248 0.06163 -0.704416 0.704416">
                                    <inertial pos="-8.0726e-06 0.0085838 -0.0049566" quat="0.479044 0.515636 -0.513069 0.491321" mass="0.3292" diaginertia="0.000360268 0.000311078 0.000214984" />
                                    <joint name="right_j6" pos="0 0 0" axis="0 0 1" limited="true" range="-4.7124 4.7124" />
                                    <geom type="mesh" rgba="0.5 0.1 0.1 1" mesh="l6" />
                                    <geom size="0.035 0.015" pos="0 0 0.0445" quat="0.707107 0 0 0.707107" type="cylinder" />
                                </body>
                            </body>
                        </body>
                    </body>
                </body>
            </body>
        </body>
    </worldbody>
</mujoco>
